Workbook

Sheet Form Responses 1
B2: Common Data Model MHTED Dashboard
B3: 1 | C3: 2 | D3: 3 | E3: 4 | F3: 5 | G3: 6 | H3: 7 | I3: 8 | J3: 9 | K3: 10 | L3: 11 | M3: 12 | N3: 13 | O3: 14 | P3: 15 | Q3: 16 | R3: 17 | S3: 18 | T3: 19 | U3: 20 | V3: 21 | W3: 22 | X3: 23 | Y3: 24 | Z3: 25 | AA3: 26 | AB3: 27 | AC3: 28 | AD3: 29 | AE3: 30 | AF3: 31 | AG3: 32 | AH3: 33 | AI3: 34 | AJ3: 35 | AK3: 36 | AL3: 37 | AM3: 38 | AN3: 39 | AO3: 40 | AP3: 41 | AQ3: 42 | AR3: 43 | AS3: 44 | AT3: 45
B4: Academic Year | C4: University AISHE Code | D4: University Name | E4: College Code (University's Internal Code) | F4: College Name | G4: College State | H4: College District | I4: College Taluka | J4: College City / Village Name | K4: College Pin Code | L4: Application Form No. | M4: Admission Date | N4: Gender (Male/Female/Transgender) | O4: Religion (Hindu,Muslim,Christian, Parsi,Buddhist,Sikh,jain, Jew) | P4: Category (EWS,Foreign National,General, Not Available,OBC,Others,PWD,SBC, SC, SEBC,ST,VJ, NT) | Q4: Cast Name (e.g Brahmin/Sonar/...) | R4: Admitted Category (EWS,Foreign National,General, Not Available,OBC,Others,PWD,SBC, SC, SEBC,ST,VJ, NT) | S4: Student Location Category (Rural/Urban) | T4: Student Country | U4: Student State | V4: Student District | W4: Student Taluka | X4: Student City / Village | Y4: Student Location Pin Code | Z4: University PRN | AA4: Student ID | AB4: pk_Receipt_ ID | AC4: Receipt Number | AD4: Receipt Amount | AE4: Physical Disability Enter the Disabilities of the Sttudents (Blindness,Low Vision,Hearing Impairment,Locomotor Disability,Leprosy Cured,Mental illness,Cerebral Palsy,Intellectual Disability,Muscular Dystrophy Parkinson's Disease,Acid Attack Victim,Sickle Cell Disease,Haemophilia,Thalassemia, Speech and Language Disabilities, Multiple Sclerosis,Specific Learning Disabilities,Chronic Neurological Conditions,Autism Spectrum Disorder Dwarfism) | AF4: Marital Status (Deserted,Divorced, Married, Unmarried, Widowed) | AG4: Medium of Appearance (Enter Medium of Appearance selected by students (MARATHI, ENGLISH, HINDI, SANSKRIT, URDU, ARABIC, UNJABI, GUJARAT, KONKANI, FRENCH, GERMAN, JAPANESE, SPANISH, RUSSIAN) | AH4: Medium of Instructions (Enter Medium of instructions selected by students (MARATHI, ENGLISH, HINDI, SANSKRIT, URDU, ARABIC, UNJABI, GUJARAT, KONKANI, FRENCH, GERMAN, JAPANESE, SPANISH, RUSSIAN, PALI) | AI4: Mode of Learning Regular / Online/ Open/ Distance/ Blended | AJ4: Program Code | AK4: Program Code (Name of the course under program type) | AL4: Specialization | AM4: Program Type (Phd./UG/PG/PGDM/Diploma/Certifications) | AN4: Program Part (First Year, Second Year, Third Year, Fourth Year, Fifth Year) | AO4: Program Term (Sem1, Sem.2, Sem 3, Sem 4, Sem 5, Sem 6, Sem 7, Sem 8,) | AP4: Eligibility Status (Provisional, Not Eligible, Eligible) | AQ4: Eligibility Date ( / / ) | AR4: All Documents Submitted (Yes or No) | AS4: Pending Documents Count (Number) (O, if null) | AT4: APAAR ID (ABC ID) (12 - digit number APAAR ID of students that is earlier known as ABC ID (123456789012))
B5: 2024-25 | D5: DR. BABASAHEB AMBEDKAR TECHNOLOGICAL UNIVERSITY, LONERE, RAIGAD | E5: EN-6036 | F5: Government College Of Engineering Kolhapur | G5: Maharashtra | H5: Kolhapur | I5: Karveer | J5: Kolhapur | K5: 416004
S9: ()

Sheet 6036
B1: Government College Of Engineering Kolhapur-6036
B2: Common Data Model MHTED Dashboard
B3: 1 | C3: 2 | D3: 3 | E3: 4 | F3: 5 | G3: 6 | H3: 7 | I3: 8 | J3: 9 | K3: 10 | L3: 11 | M3: 12 | N3: 13 | O3: 14 | P3: 15 | Q3: 16 | R3: 17 | S3: 18 | T3: 19 | U3: 20 | V3: 21 | W3: 22 | X3: 23 | Y3: 24 | Z3: 25 | AA3: 26 | AB3: 27 | AC3: 28 | AD3: 29 | AE3: 30 | AF3: 31 | AG3: 32 | AH3: 33 | AI3: 34 | AJ3: 35 | AK3: 36 | AL3: 37 | AM3: 38 | AN3: 39 | AO3: 40 | AP3: 41 | AQ3: 42 | AR3: 43 | AS3: 44 | AT3: 45
B4: Column1 | C4: Column2 | D4: Column3 | E4: Column4 | F4: Column5 | G4: Column6 | H4: Column7 | I4: Column8 | J4: Column9 | K4: Column10 | L4: Column11 | M4: Column12 | N4: Column13 | O4: Column14 | P4: Column15 | Q4: Column16 | R4: Column17 | S4: Column18 | T4: Column19 | U4: Column20 | V4: Column21 | W4: Column22 | X4: Column23 | Y4: Column24 | Z4: Column25 | AA4: Column26 | AB4: Column27 | AC4: Column28 | AD4: Column29 | AE4: Column30 | AF4: Column31 | AG4: Column32 | AH4: Column33 | AI4: Column34 | AJ4: Column35 | AK4: Column36 | AL4: Column37 | AM4: Column38 | AN4: Column39 | AO4: Column40 | AP4: Column41 | AQ4: Column42 | AR4: Column43 | AS4: Column44 | AT4: Column45
B5: Academic Year | C5: University AISHE Code | D5: University Name | E5: College Code (University's Internal Code) | F5: College Name | G5: College State | H5: College District | I5: College Taluka | J5: College City / Village Name | K5: College Pin Code | L5: Application Form No. | M5: Admission Date | N5: Gender (Male/Female/Transgender) | O5: Religion (Hindu,Muslim,Christian, Parsi,Buddhist,Sikh,jain, Jew) | P5: Category (EWS,Foreign National,General, Not Available,OBC,Others,PWD,SBC, SC, SEBC,ST,VJ, NT) | Q5: Cast Name (e.g Brahmin/Sonar/...) | R5: Admitted Category (EWS,Foreign National,General, Not Available,OBC,Others,PWD,SBC, SC, SEBC,ST,VJ, NT) | S5: Student Location Category (Rural/Urban) | T5: Student Country | U5: Student State | V5: Student District | W5: Student Taluka | X5: Student City / Village | Y5: Student Location Pin Code | Z5: University PRN | AA5: Student ID | AB5: pk_Receipt_ ID | AC5: Receipt Number | AD5: Receipt Amount | AE5: Physical Disability Enter the Disabilities of the Sttudents (Blindness,Low Vision,Hearing Impairment,Locomotor Disability,Leprosy Cured,Mental illness,Cerebral Palsy,Intellectual Disability,Muscular Dystrophy Parkinson's Disease,Acid Attack Victim,Sickle Cell Disease,Haemophilia,Thalassemia, Speech and Language Disabilities, Multiple Sclerosis,Specific Learning Disabilities,Chronic Neurological Conditions,Autism Spectrum Disorder Dwarfism) | AF5: Marital Status (Deserted,Divorced, Married, Unmarried, Widowed) | AG5: Medium of Appearance (Enter Medium of Appearance selected by students (MARATHI, ENGLISH, HINDI, SANSKRIT, URDU, ARABIC, UNJABI, GUJARAT, KONKANI, FRENCH, GERMAN, JAPANESE, SPANISH, RUSSIAN) | AH5: Medium of Instructions (Enter Medium of instructions selected by students (MARATHI, ENGLISH, HINDI, SANSKRIT, URDU, ARABIC, UNJABI, GUJARAT, KONKANI, FRENCH, GERMAN, JAPANESE, SPANISH, RUSSIAN, PALI) | AI5: Mode of Learning Regular / Online/ Open/ Distance/ Blended | AJ5: Program Code | AK5: Program Code (Name of the course under program type) | AL5: Specialization | AM5: Program Type (Phd./UG/PG/PGDM/Diploma/Certifications) | AN5: Program Part (First Year, Second Year, Third Year, Fourth Year, Fifth Year) | AO5: Program Term (Sem1, Sem.2, Sem 3, Sem 4, Sem 5, Sem 6, Sem 7, Sem 8,) | AP5: Eligibility Status (Provisional, Not Eligible, Eligible) | AQ5: Eligibility Date ( / / ) | AR5: All Documents Submitted (Yes or No) | AS5: Pending Documents Count (Number) (O, if null) | AT5: APAAR ID (ABC ID) (12 - digit number APAAR ID of students that is earlier known as ABC ID (123456789012))
B6: 2024-25 | C6: C-70713 | D6: DR. BABASAHEB AMBEDKAR TECHNOLOGICAL UNIVERSITY, LONERE, RAIGAD | E6: 6036 | F6: Government College Of Engineering Kolhapur | G6: Maharashtra | H6: Kolhapur | I6: Karveer | J6: Kolhapur | K6: 416004 | L6: EN23156538 | N6: Male | O6: Hindu | P6: Open | R6: EWS | S6: Rural | T6: India | U6: Maharashtra | V6: Sangli | W6: Walwa | X6: Uran Islampur (M Cl) | Y6: 415409 | Z6: 23060361242001 | AA6: 23149 | AB6: 2024-25/320 | AC6: 2024-25/320 | AD6: 17546/- | AE6: Not Applicable | AF6: Unmarried | AG6: English | AH6: English | AI6: Regular | AJ6: 11242 | AK6: Computer Science and Engineering | AM6: UG | AN6: Second Year | AO6: Sem 3,sem4 | AP6: Elligible | AQ6: 45509 | AR6: Yes | AS6: 0 | AT6: 605880265207
B7: 2024-25 | C7: C-70713 | D7: DR. BABASAHEB AMBEDKAR TECHNOLOGICAL UNIVERSITY, LONERE, RAIGAD | E7: 6036 | F7: Government College Of Engineering Kolhapur | G7: Maharashtra | H7: Kolhapur | I7: Karveer | J7: Kolhapur | K7: 416004 | L7: EN23270294 | N7: Male | O7: Hindu | P7: OBC | R7: GOBCO | S7: Rural | T7: India | U7: Maharashtra | V7: Jalgaon | W7: Dharangaon | X7: Rotwad | Y7: 425105 | Z7: 23060361242002 | AA7: 23146 | AB7: 2023-24/321 | AC7: 2023-24/321 | AD7: 10046/- | AE7: Not Applicable | AF7: Unmarried | AG7: English | AH7: English | AI7: Regular | AJ7: 11242 | AK7: Computer Science and Engineering | AM7: UG | AN7: Second Year | AO7: Sem 3,sem4 | AP7: Elligible | AQ7: 45509 | AR7: Yes | AS7: 0 | AT7: 836028351886
B8: 2024-25 | C8: C-70713 | D8: DR. BABASAHEB AMBEDKAR TECHNOLOGICAL UNIVERSITY, LONERE, RAIGAD | E8: 6036 | F8: Government College Of Engineering Kolhapur | G8: Maharashtra | H8: Kolhapur | I8: Karveer | J8: Kolhapur | K8: 416004 | L8: EN23253637 | N8: Male | O8: Hindu | P8: Open | R8: ACAP | S8: Rural | T8: India | U8: Maharashtra | V8: Raigad | W8: Khalapur | X8: Honad | Y8: 410203 | Z8: 23060361242003 | AA8: 23108 | AB8: 2024-25/321 | AC8: 2024-25/321 | AD8: 26046/- | AE8: Not Applicable | AF8: Unmarried | AG8: English | AH8: English | AI8: Regular | AJ8: 11242 | AK8: Computer Science and Engineering | AM8: UG | AN8: Second Year | AO8: Sem 3,sem4 | AP8: Elligible | AQ8: 45509 | AR8: Yes | AS8: 0 | AT8: 323555912835
B9: 2024-25 | C9: C-70713 | D9: DR. BABASAHEB AMBEDKAR TECHNOLOGICAL UNIVERSITY, LONERE, RAIGAD | E9: 6036 | F9: Government College Of Engineering Kolhapur | G9: Maharashtra | H9: Kolhapur | I9: Karveer | J9: Kolhapur | K9: 416004 | L9: EN23254563 | N9: Male | O9: Hindu | P9: ST | R9: GSTH | S9: Rural | T9: India | U9: Maharashtra | V9: Palghar | W9: Vikramgad | X9: Vasuri | Y9: 421303 | Z9: 23060361242004 | AA9: 23112 | AB9: 2023-24/322 | AC9: 2023-24/322 | AD9: 1621/- | AE9: Not Applicable | AF9: Unmarried | AG9: English | AH9: English | AI9: Regular | AJ9: 11242 | AK9: Computer Science and Engineering | AM9: UG | AN9: Second Year | AO9: Sem 3,sem4 | AP9: Elligible | AQ9: 45509 | AR9: Yes | AS9: 0 | AT9: 802817008651
B10: 2024-25 | C10: C-70713 | D10: DR. BABASAHEB AMBEDKAR TECHNOLOGICAL UNIVERSITY, LONERE, RAIGAD | E10: 6036 | F10: Government College Of Engineering Kolhapur | G10: Maharashtra | H10: Kolhapur | I10: Karveer | J10: Kolhapur | K10: 416004 | L10: EN23187082 | N10: Male | O10: Hindu | P10: NT 2 (NT-C) | R10: GNT2H | S10: Rural | T10: India | U10: Maharashtra | V10: Sangli | W10: Atpadi | X10: Banpuri | Y10: 415306 | Z10: 23060361242005 | AA10: 23154 | AB10: 2024-25/322 | AC10: 2024-25/322 | AD10: 0/- | AE10: Not Applicable | AF10: Unmarried | AG10: English | AH10: English | AI10: Regular | AJ10: 11242 | AK10: Computer Science and Engineering | AM10: UG | AN10: Second Year | AO10: Sem 3,sem4 | AP10: Elligible | AQ10: 45509 | AR10: Yes | AS10: 0 | AT10: 267273146627
B11: 2024-25 | C11: C-70713 | D11: DR. BABASAHEB AMBEDKAR TECHNOLOGICAL UNIVERSITY, LONERE, RAIGAD | E11: 6036 | F11: Government College Of Engineering Kolhapur | G11: Maharashtra | H11: Kolhapur | I11: Karveer | J11: Kolhapur | K11: 416004 | L11: EN23251094 | N11: Male | O11: Hindu | P11: Open | R11: GOPENO | S11: Rural | T11: India | U11: Maharashtra | V11: Solapur | W11: Pandharpur | X11: Bhose | Y11: 413315 | Z11: 23060361242006 | AA11: 23167 | AB11: 2023-24/323 | AC11: 2023-24/323 | AD11: 17546/- | AE11: Not Applicable | AF11: Unmarried | AG11: English | AH11: English | AI11: Regular | AJ11: 11242 | AK11: Computer Science and Engineering | AM11: UG | AN11: Second Year | AO11: Sem 3,sem4 | AP11: Elligible | AQ11: 45509 | AR11: Yes | AS11: 0 | AT11: 781639551721
B12: 2024-25 | C12: C-70713 | D12: DR. BABASAHEB AMBEDKAR TECHNOLOGICAL UNIVERSITY, LONERE, RAIGAD | E12: 6036 | F12: Government College Of Engineering Kolhapur | G12: Maharashtra | H12: Kolhapur | I12: Karveer | J12: Kolhapur | K12: 416004 | L12: EN23250898 | N12: Female | O12: Hindu | P12: Open | R12: EWS | S12: Urban | T12: India | U12: Maharashtra | V12: Kolhapur | W12: Karvir | X12: Kolhapur (M Corp.) | Y12: 416012 | Z12: 23060361242007 | AA12: 23115 | AB12: 2024-25/323 | AC12: 2024-25/323 | AD12: 17546/- | AE12: Not Applicable | AF12: Unmarried | AG12: English | AH12: English | AI12: Regular | AJ12: 11242 | AK12: Computer Science and Engineering | AM12: UG | AN12: Second Year | AO12: Sem 3,sem4 | AP12: Elligible | AQ12: 45509 | AR12: Yes | AS12: 0 | AT12: 351040668378
B13: 2024-25 | C13: C-70713 | D13: DR. BABASAHEB AMBEDKAR TECHNOLOGICAL UNIVERSITY, LONERE, RAIGAD | E13: 6036 | F13: Government College Of Engineering Kolhapur | G13: Maharashtra | H13: Kolhapur | I13: Karveer | J13: Kolhapur | K13: 416004 | L13: EN23125066 | N13: Male | O13: Muslim | P13: Open | R13: GOPENH | S13: Urban | T13: India | U13: Maharashtra | V13: Sangli | W13: Walwa | X13: Ashta (M Cl) | Y13: 416301 | Z13: 23060361242008 | AA13: 23114 | AB13: 2023-24/324 | AC13: 2023-24/324 | AD13: 17546/- | AE13: Not Applicable | AF13: Unmarried | AG13: English | AH13: English | AI13: Regular | AJ13: 11242 | AK13: Computer Science and Engineering | AM13: UG | AN13: Second Year | AO13: Sem 3,sem4 | AP13: Elligible | AQ13: 45509 | AR13: Yes | AS13: 0 | AT13: 660158417433
B14: 2024-25 | C14: C-70713 | D14: DR. BABASAHEB AMBEDKAR TECHNOLOGICAL UNIVERSITY, LONERE, RAIGAD | E14: 6036 | F14: Government College Of Engineering Kolhapur | G14: Maharashtra | H14: Kolhapur | I14: Karveer | J14: Kolhapur | K14: 416004 | L14: EN23165043 | N14: Male | O14: Hindu | P14: ST | R14: GSTH | S14: Urban | T14: India | U14: Maharashtra | V14: Chandrapur | W14: Chandrapur | X14: Chandrapur | Y14: 442401 | Z14: 23060361242009 | AA14: 23135 | AB14: 2024-25/324 | AC14: 2024-25/324 | AD14: 1621/- | AE14: Not Applicable | AF14: Unmarried | AG14: English | AH14: English | AI14: Regular | AJ14: 11242 | AK14: Computer Science and Engineering | AM14: UG | AN14: Second Year | AO14: Sem 3,sem4 | AP14: Elligible | AQ14: 45509 | AR14: Yes | AS14: 0 | AT14: 407782827857
B15: 2024-25 | C15: C-70713 | D15: DR. BABASAHEB AMBEDKAR TECHNOLOGICAL UNIVERSITY, LONERE, RAIGAD | E15: 6036 | F15: Government College Of Engineering Kolhapur | G15: Maharashtra | H15: Kolhapur | I15: Karveer | J15: Kolhapur | K15: 416004 | L15: EN23234429 | N15: Male | O15: Hindu | P15: OBC | R15: ACAP | S15: Rural | T15: India | U15: Maharashtra | V15: Aurangabad | W15: Aurangabad | X15: Aurangabad (M Corp.) | Y15: 431136 | Z15: 23060361242010 | AA15: 23136 | AB15: 2023-24/325 | AC15: 2023-24/325 | AD15: 25046/- | AE15: Not Applicable | AF15: Unmarried | AG15: English | AH15: English | AI15: Regular | AJ15: 11242 | AK15: Computer Science and Engineering | AM15: UG | AN15: Second Year | AO15: Sem 3,sem4 | AP15: Elligible | AQ15: 45509 | AR15: Yes | AS15: 0 | AT15: 641151883947
B16: 2024-25 | C16: C-70713 | D16: DR. BABASAHEB AMBEDKAR TECHNOLOGICAL UNIVERSITY, LONERE, RAIGAD | E16: 6036 | F16: Government College Of Engineering Kolhapur | G16: Maharashtra | H16: Kolhapur | I16: Karveer | J16: Kolhapur | K16: 416004 | L16: EN23245684 | N16: Female | O16: Hindu | P16: NT 2 (NT-C) | R16: LOPENH | S16: Rural | T16: India | U16: Maharashtra | V16: Sangli | W16: Jat | X16: Khairao | Y16: 416404 | Z16: 23060361242011 | AA16: 23106 | AB16: 2024-25/325 | AC16: 2024-25/325 | AD16: 10046/- | AE16: Not Applicable | AF16: Unmarried | AG16: English | AH16: English | AI16: Regular | AJ16: 11242 | AK16: Computer Science and Engineering | AM16: UG | AN16: Second Year | AO16: Sem 3,sem4 | AP16: Elligible | AQ16: 45509 | AR16: Yes | AS16: 0 | AT16: 230336667045
B17: 2024-25 | C17: C-70713 | D17: DR. BABASAHEB AMBEDKAR TECHNOLOGICAL UNIVERSITY, LONERE, RAIGAD | E17: 6036 | F17: Government College Of Engineering Kolhapur | G17: Maharashtra | H17: Kolhapur | I17: Karveer | J17: Kolhapur | K17: 416004 | L17: EN23258899 | N17: Male | O17: Hindu | P17: OBC | R17: PWDOPENH | S17: Urban | T17: India | U17: Maharashtra | V17: Buldhana | W17: Chikhli | X17: Chikhli (M Cl) | Y17: 443201 | Z17: 23060361242012 | AA17: 23104 | AB17: 2023-24/326 | AC17: 2023-24/326 | AD17: 10046/- | AE17: Low-Vision | AF17: Unmarried | AG17: English | AH17: English | AI17: Regular | AJ17: 11242 | AK17: Computer Science and Engineering | AM17: UG | AN17: Second Year | AO17: Sem 3,sem4 | AP17: Elligible | AQ17: 45509 | AR17: Yes | AS17: 0 | AT17: 298767095627
... B159: 2024-25 | C159: C-70713 | D159: DR. BABASAHEB AMBEDKAR TECHNOLOGICAL UNIVERSITY, LONERE, RAIGAD | E159: 6036 | F159: Government College Of Engineering Kolhapur | G159: Maharashtra | H159: Kolhapur | I159: Karveer | J159: Kolhapur | K159: 416004 | L159: EN23166695 | N159: Male | O159: Hindu | P159: NT 2 (NT-C) | R159: PWDOPENH | S159: Rural | T159: India | U159: Maharashtra | V159: Sangli | W159: Miraj | X159: Sangli Miraj Kupwad (M Corp.) | Y159: 416416 | Z159: 23060361293020 | AA159: 23429 | AB159: 2023-24/397 | AC159: 2023-24/397 | AD159: 10046/- | AE159: Not Applicable | AF159: Unmarried | AG159: English | AH159: English | AI159: Regular | AJ159: 11293 | AK159: Electrical Engineering | AM159: UG | AN159: Second Year | AO159: Sem 3,sem4 | AP159: Elligible | AQ159: 45509 | AR159: Yes | AS159: 0 | AT159: 189004584253
B160: 2024-25 | C160: C-70713 | D160: DR. BABASAHEB AMBEDKAR TECHNOLOGICAL UNIVERSITY, LONERE, RAIGAD | E160: 6036 | F160: Government College Of Engineering Kolhapur | G160: Maharashtra | H160: Kolhapur | I160: Karveer | J160: Kolhapur | K160: 416004 | L160: EN23125670 | N160: Male | O160: Hindu | P160: OBC | R160: LSTO | S160: Rural | T160: India | U160: Maharashtra | V160: Latur | W160: Shirur-Anantpal | X160: Sakol | Y160: 413544 | Z160: 23060361293021 | AA160: 23434 | AB160: 2024-25/397 | AC160: 2024-25/397 | AD160: 10046/- | AE160: Not Applicable | AF160: Unmarried | AG160: English | AH160: English | AI160: Regular | AJ160: 11293 | AK160: Electrical Engineering | AM160: UG | AN160: Second Year | AO160: Sem 3,sem4 | AP160: Not Elligible | AQ160: 45509 | AR160: Yes | AS160: 0
B161: 2024-25 | C161: C-70713 | D161: DR. BABASAHEB AMBEDKAR TECHNOLOGICAL UNIVERSITY, LONERE, RAIGAD | E161: 6036 | F161: Government College Of Engineering Kolhapur | G161: Maharashtra | H161: Kolhapur | I161: Karveer | J161: Kolhapur | K161: 416004 | L161: EN23188796 | N161: Male | O161: Hindu | P161: SC | R161: GSCO | S161: Rural | T161: India | U161: Maharashtra | V161: Latur | W161: Udgir | X161: Bhakaskheda | Y161: 413517 | Z161: 23060361293022 | AA161: 23425 | AB161: 2023-24/398 | AC161: 2023-24/398 | AD161: 10046/- | AE161: Not Applicable | AF161: Unmarried | AG161: English | AH161: English | AI161: Regular | AJ161: 11293 | AK161: Electrical Engineering | AM161: UG | AN161: Second Year | AO161: Sem 3,sem4 | AP161: Elligible | AQ161: 45509 | AR161: Yes | AS161: 0 | AT161: 873629757191
B162: 2024-25 | C162: C-70713 | D162: DR. BABASAHEB AMBEDKAR TECHNOLOGICAL UNIVERSITY, LONERE, RAIGAD | E162: 6036 | F162: Government College Of Engineering Kolhapur | G162: Maharashtra | H162: Kolhapur | I162: Karveer | J162: Kolhapur | K162: 416004 | L162: EN23208843 | N162: Male | O162: Hindu | P162: OBC | R162: GOBCH | S162: Rural | T162: India | U162: Maharashtra | V162: Aurangabad | W162: Aurangabad | X162: Pimpalgaon Pandhari | Y162: 431121 | Z162: 23060361293023 | AA162: 23422 | AB162: 2024-25/398 | AC162: 2024-25/398 | AD162: 1621/- | AE162: Not Applicable | AF162: Unmarried | AG162: English | AH162: English | AI162: Regular | AJ162: 11293 | AK162: Electrical Engineering | AM162: UG | AN162: Second Year | AO162: Sem 3,sem4 | AP162: Elligible | AQ162: 45509 | AR162: Yes | AS162: 0 | AT162: 360708739294
B163: 2024-25 | C163: C-70713 | D163: DR. BABASAHEB AMBEDKAR TECHNOLOGICAL UNIVERSITY, LONERE, RAIGAD | E163: 6036 | F163: Government College Of Engineering Kolhapur | G163: Maharashtra | H163: Kolhapur | I163: Karveer | J163: Kolhapur | K163: 416004 | L163: EN23223410 | N163: Male | O163: Hindu | P163: Open | R163: GSTH | S163: Rural | T163: India | U163: Maharashtra | V163: Kolhapur | W163: Kagal | X163: Sake | Y163: 416221 | Z163: 23060361293024 | AA163: 23401 | AB163: 2023-24/399 | AC163: 2023-24/399 | AD163: 10046/- | AE163: Not Applicable | AF163: Unmarried | AG163: English | AH163: English | AI163: Regular | AJ163: 11293 | AK163: Electrical Engineering | AM163: UG | AN163: Second Year | AO163: Sem 3,sem4 | AP163: Not Elligible | AQ163: 45509 | AR163: Yes | AS163: 0 | AT163: 608950228983
B164: 2024-25 | C164: C-70713 | D164: DR. BABASAHEB AMBEDKAR TECHNOLOGICAL UNIVERSITY, LONERE, RAIGAD | E164: 6036 | F164: Government College Of Engineering Kolhapur | G164: Maharashtra | H164: Kolhapur | I164: Karveer | J164: Kolhapur | K164: 416004 | L164: EN23223423 | N164: Male | O164: Hindu | P164: Open | R164: GSTH | S164: Rural | T164: India | U164: Maharashtra | V164: Jaunpur | W164: Not Applicable | X164: Not Applicable | Y164: 222170 | Z164: 23060361293025 | AA164: 23464 | AB164: 2024-25/399 | AC164: 2024-25/399 | AD164: 25046/- | AE164: Not Applicable | AF164: Unmarried | AG164: English | AH164: English | AI164: Regular | AJ164: 11293 | AK164: Electrical Engineering | AM164: UG | AN164: Second Year | AO164: Sem 3,sem4 | AP164: Elligible | AQ164: 45509 | AR164: Yes | AS164: 0 | AT164: 241698527714
B165: 2024-25 | C165: C-70713 | D165: DR. BABASAHEB AMBEDKAR TECHNOLOGICAL UNIVERSITY, LONERE, RAIGAD | E165: 6036 | F165: Government College Of Engineering Kolhapur | G165: Maharashtra | H165: Kolhapur | I165: Karveer | J165: Kolhapur | K165: 416004 | L165: EN23154576 | N165: Male | O165: Hindu | P165: OBC | R165: GOBCH | S165: Rural | T165: India | U165: Maharashtra | V165: Kolhapur | W165: Radhanagari | X165: Phejiwade | Y165: 416212 | Z165: 23060361293026 | AA165: 23416 | AB165: 2023-24/400 | AC165: 2023-24/400 | AD165: 10046/- | AE165: Not Applicable | AF165: Unmarried | AG165: English | AH165: English | AI165: Regular | AJ165: 11293 | AK165: Electrical Engineering | AM165: UG | AN165: Second Year | AO165: Sem 3,sem4 | AP165: Elligible | AQ165: 45509 | AR165: Yes | AS165: 0 | AT165: 181597049790
B166: 2024-25 | C166: C-70713 | D166: DR. BABASAHEB AMBEDKAR TECHNOLOGICAL UNIVERSITY, LONERE, RAIGAD | E166: 6036 | F166: Government College Of Engineering Kolhapur | G166: Maharashtra | H166: Kolhapur | I166: Karveer | J166: Kolhapur | K166: 416004 | L166: EN23155827 | N166: Male | O166: Hindu | P166: OBC | R166: GOBCO | S166: Rural | T166: India | U166: Maharashtra | V166: Nagpur | W166: Savner | X166: Bhanegaon | Y166: 441102 | Z166: 23060361293027 | AA166: 23412 | AB166: 2024-25/400 | AC166: 2024-25/400 | AD166: 10046/- | AE166: Not Applicable | AF166: Unmarried | AG166: English | AH166: English | AI166: Regular | AJ166: 11293 | AK166: Electrical Engineering | AM166: UG | AN166: Second Year | AO166: Sem 3,sem4 | AP166: Elligible | AQ166: 45509 | AR166: Yes | AS166: 0 | AT166: 595794677349
B167: 2024-25 | C167: C-70713 | D167: DR. BABASAHEB AMBEDKAR TECHNOLOGICAL UNIVERSITY, LONERE, RAIGAD | E167: 6036 | F167: Government College Of Engineering Kolhapur | G167: Maharashtra | H167: Kolhapur | I167: Karveer | J167: Kolhapur | K167: 416004 | L167: EN23193465 | N167: Female | O167: Hindu | P167: OBC | R167: GOBCO | S167: Urban | T167: India | U167: Maharashtra | V167: Solapur | W167: Pandharpur | X167: Pandharpur (M Cl) | Y167: 413304 | Z167: 23060361293028 | AA167: 23462 | AB167: 2023-24/401 | AC167: 2023-24/401 | AD167: 10046/- | AE167: Not Applicable | AF167: Unmarried | AG167: English | AH167: English | AI167: Regular | AJ167: 11293 | AK167: Electrical Engineering | AM167: UG | AN167: Second Year | AO167: Sem 3,sem4 | AP167: Elligible | AQ167: 45509 | AR167: Yes | AS167: 0 | AT167: 998886918164
B168: 2024-25 | C168: C-70713 | D168: DR. BABASAHEB AMBEDKAR TECHNOLOGICAL UNIVERSITY, LONERE, RAIGAD | E168: 6036 | F168: Government College Of Engineering Kolhapur | G168: Maharashtra | H168: Kolhapur | I168: Karveer | J168: Kolhapur | K168: 416004 | L168: EN23156522 | N168: Female | O168: Hindu | P168: Open | R168: LOPENH | S168: Rural | T168: India | U168: Maharashtra | V168: Sangli | W168: Palus | X168: Kundal | Y168: 416309 | Z168: 23060361293029 | AA168: 23432 | AB168: 2024-25/401 | AC168: 2024-25/401 | AD168: 17546/- | AE168: Not Applicable | AF168: Unmarried | AG168: English | AH168: English | AI168: Regular | AJ168: 11293 | AK168: Electrical Engineering | AM168: UG | AN168: Second Year | AO168: Sem 3,sem4 | AP168: Elligible | AQ168: 45509 | AR168: Yes | AS168: 0 | AT168: 503442678074
B169: 2024-25 | C169: C-70713 | D169: DR. BABASAHEB AMBEDKAR TECHNOLOGICAL UNIVERSITY, LONERE, RAIGAD | E169: 6036 | F169: Government College Of Engineering Kolhapur | G169: Maharashtra | H169: Kolhapur | I169: Karveer | J169: Kolhapur | K169: 416004 | L169: EN23149018 | N169: Female | O169: Hindu | P169: Open | R169: PWDOPENH | S169: Rural | T169: India | U169: Maharashtra | V169: Sangli | W169: Walwa | X169: Mirajwadi | Y169: 416301 | Z169: 23060361293030 | AA169: 23455 | AB169: 2023-24/402 | AC169: 2023-24/402 | AD169: 17546/- | AE169: Not Applicable | AF169: Unmarried | AG169: English | AH169: English | AI169: Regular | AJ169: 11293 | AK169: Electrical Engineering | AM169: UG | AN169: Second Year | AO169: Sem 3,sem4 | AP169: Elligible | AQ169: 45509 | AR169: Yes | AS169: 0 | AT169: 930906101291
B170: 2024-25 | C170: C-70713 | D170: DR. BABASAHEB AMBEDKAR TECHNOLOGICAL UNIVERSITY, LONERE, RAIGAD | E170: 6036 | F170: Government College Of Engineering Kolhapur | G170: Maharashtra | H170: Kolhapur | I170: Karveer | J170: Kolhapur | K170: 416004 | L170: EN23219719 | N170: Male | O170: Hindu | P170: Open | R170: GOPENH | S170: Rural | T170: India | U170: Maharashtra | V170: Sangli | W170: Tasgaon | X170: Savarde | Y170: 416408 | Z170: 23060361293031 | AA170: 23419 | AB170: 2024-25/402 | AC170: 2024-25/402 | AD170: 17546/- | AE170: Not Applicable | AF170: Unmarried | AG170: English | AH170: English | AI170: Regular | AJ170: 11293 | AK170: Electrical Engineering | AM170: UG | AN170: Second Year | AO170: Sem 3,sem4 | AP170: Elligible | AQ170: 45509 | AR170: Yes | AS170: 0 | AT170: 806310517432
B171: 2024-25 | C171: C-70713 | D171: DR. BABASAHEB AMBEDKAR TECHNOLOGICAL UNIVERSITY, LONERE, RAIGAD | E171: 6036 | F171: Government College Of Engineering Kolhapur | G171: Maharashtra | H171: Kolhapur | I171: Karveer | J171: Kolhapur | K171: 416004 | L171: EN23239733 | N171: Female | O171: Hindu | P171: SC | R171: LSCO | S171: Urban | T171: India | U171: Maharashtra | V171: Osmanabad | W171: Osmanabad | X171: Osmanabad | Y171: 413501 | Z171: 23060361293032 | AA171: 23417 | AB171: 2023-24/403 | AC171: 2023-24/403 | AD171: 1621/- | AE171: Not Applicable | AF171: Unmarried | AG171: English | AH171: English | AI171: Regular | AJ171: 11293 | AK171: Electrical Engineering | AM171: UG | AN171: Second Year | AO171: Sem 3,sem4 | AP171: Not Elligible | AQ171: 45509 | AR171: Yes | AS171: 0 | AT171: 656744872517
B172: 2024-25 | C172: C-70713 | D172: DR. BABASAHEB AMBEDKAR TECHNOLOGICAL UNIVERSITY, LONERE, RAIGAD | E172: 6036 | F172: Government College Of Engineering Kolhapur | G172: Maharashtra | H172: Kolhapur | I172: Karveer | J172: Kolhapur | K172: 416004 | L172: EN23163807 | N172: Female | O172: Buddhist | P172: SC | R172: LSCH | S172: Rural | T172: India | U172: Maharashtra | V172: Satara | W172: Karad | X172: Ving | Y172: 415122 | Z172: 23060361293033 | AA172: 23459 | AB172: 2024-25/403 | AC172: 2024-25/403 | AD172: 1621/- | AE172: Not Applicable | AF172: Unmarried | AG172: English | AH172: English | AI172: Regular | AJ172: 11293 | AK172: Electrical Engineering | AM172: UG | AN172: Second Year | AO172: Sem 3,sem4 | AP172: Elligible | AQ172: 45509 | AR172: Yes | AS172: 0 | AT172: 514286613258
... B192: 2024-25 | C192: C-70713 | D192: DR. BABASAHEB AMBEDKAR TECHNOLOGICAL UNIVERSITY, LONERE, RAIGAD | E192: 6036 | F192: Government College Of Engineering Kolhapur | G192: Maharashtra | H192: Kolhapur | I192: Karveer | J192: Kolhapur | K192: 416004 | L192: EN23205254 | N192: Male | O192: Hindu | P192: Open | R192: GOPENH | S192: Rural | T192: India | U192: Maharashtra | V192: Sangli | W192: Shirala | X192: Red | Y192: 415408 | Z192: 23060361293053 | AA192: 23423 | AB192: 2024-25/413 | AC192: 2024-25/413 | AD192: 10046/- | AE192: Not Applicable | AF192: Unmarried | AG192: English | AH192: English | AI192: Regular | AJ192: 11293 | AK192: Electrical Engineering | AM192: UG | AN192: Second Year | AO192: Sem 3,sem4 | AP192: Elligible | AQ192: 45509 | AR192: Yes | AS192: 0 | AT192: 437525703191
B193: 2024-25 | C193: C-70713 | D193: DR. BABASAHEB AMBEDKAR TECHNOLOGICAL UNIVERSITY, LONERE, RAIGAD | E193: 6036 | F193: Government College Of Engineering Kolhapur | G193: Maharashtra | H193: Kolhapur | I193: Karveer | J193: Kolhapur | K193: 416004 | L193: EN23193751 | N193: Male | O193: Hindu | P193: Open | R193: TFWS | S193: Rural | T193: India | U193: Maharashtra | V193: Kolhapur | W193: Shahuwadi | X193: Rethare | Y193: 416214 | Z193: 23060361293054 | AA193: 23405 | AB193: 2023-24/414 | AC193: 2023-24/414 | AE193: Not Applicable | AF193: Unmarried | AG193: English | AH193: English | AI193: Regular | AJ193: 11293 | AK193: Electrical Engineering | AM193: UG | AN193: Second Year | AO193: Sem 3,sem4 | AP193: Elligible | AQ193: 45509 | AR193: Yes | AS193: 0 | AT193: 889487254520
B194: 2024-25 | C194: C-70713 | D194: DR. BABASAHEB AMBEDKAR TECHNOLOGICAL UNIVERSITY, LONERE, RAIGAD | E194: 6036 | F194: Government College Of Engineering Kolhapur | G194: Maharashtra | H194: Kolhapur | I194: Karveer | J194: Kolhapur | K194: 416004 | L194: EN23128578 | N194: Female | O194: Hindu | P194: Open | R194: DEFOPENS | S194: Urban | T194: India | U194: Maharashtra | V194: Satara | W194: Karad | X194: Karad (M Cl) | Y194: 415124 | Z194: 23060361293055 | AA194: 23420 | AB194: 2024-25/414 | AC194: 2024-25/414 | AD194: 17546/- | AE194: Not Applicable | AF194: Unmarried | AG194: English | AH194: English | AI194: Regular | AJ194: 11293 | AK194: Electrical Engineering | AM194: UG | AN194: Second Year | AO194: Sem 3,sem4 | AP194: Elligible | AQ194: 45509 | AR194: Yes | AS194: 0 | AT194: 552915960282
B195: 2024-25 | C195: C-70713 | D195: DR. BABASAHEB AMBEDKAR TECHNOLOGICAL UNIVERSITY, LONERE, RAIGAD | E195: 6036 | F195: Government College Of Engineering Kolhapur | G195: Maharashtra | H195: Kolhapur | I195: Karveer | J195: Kolhapur | K195: 416004 | L195: EN23244599 | N195: Female | O195: Hindu | P195: Open | R195: LOPENH | S195: Rural | T195: India | U195: Maharashtra | V195: Satara | W195: Patan | X195: Nisare | Y195: 415205 | Z195: 23060361293056 | AA195: 23421 | AB195: 2023-24/415 | AC195: 2023-24/415 | AD195: 17546/- | AE195: Not Applicable | AF195: Unmarried | AG195: English | AH195: English | AI195: Regular | AJ195: 11293 | AK195: Electrical Engineering | AM195: UG | AN195: Second Year | AO195: Sem 3,sem4 | AP195: Elligible | AQ195: 45509 | AR195: Yes | AS195: 0 | AT195: 123607223938
B196: 2024-25 | C196: C-70713 | D196: DR. BABASAHEB AMBEDKAR TECHNOLOGICAL UNIVERSITY, LONERE, RAIGAD | E196: 6036 | F196: Government College Of Engineering Kolhapur | G196: Maharashtra | H196: Kolhapur | I196: Karveer | J196: Kolhapur | K196: 416004 | L196: EN23250182 | N196: Female | O196: Hindu | P196: Open | R196: LOPENO | S196: Rural | T196: India | U196: Maharashtra | V196: Solapur | W196: Barshi | X196: Kuslamb | Y196: 413401 | Z196: 23060361293057 | AA196: 23426 | AB196: 2024-25/415 | AC196: 2024-25/415 | AD196: 0/- | AE196: Not Applicable | AF196: Unmarried | AG196: English | AH196: English | AI196: Regular | AJ196: 11293 | AK196: Electrical Engineering | AM196: UG | AN196: Second Year | AO196: Sem 3,sem4 | AP196: Elligible | AQ196: 45509 | AR196: Yes | AS196: 0 | AT196: 541629007547
B197: 2024-25 | C197: C-70713 | D197: DR. BABASAHEB AMBEDKAR TECHNOLOGICAL UNIVERSITY, LONERE, RAIGAD | E197: 6036 | F197: Government College Of Engineering Kolhapur | G197: Maharashtra | H197: Kolhapur | I197: Karveer | J197: Kolhapur | K197: 416004 | L197: EN23272605 | N197: Male | O197: Hindu | P197: SBC | R197: GOPENH | S197: Rural | T197: India | U197: Maharashtra | V197: Kolhapur | W197: Hatkanangle | X197: Rukadi | Y197: 416118 | Z197: 23060361293058 | AA197: 23430 | AB197: 2023-24/416 | AC197: 2023-24/416 | AD197: 10046/- | AE197: Not Applicable | AF197: Unmarried | AG197: English | AH197: English | AI197: Regular | AJ197: 11293 | AK197: Electrical Engineering | AM197: UG | AN197: Second Year | AO197: Sem 3,sem4 | AP197: Elligible | AQ197: 45509 | AR197: Yes | AS197: 0 | AT197: 790613157226
B198: 2024-25 | C198: C-70713 | D198: DR. BABASAHEB AMBEDKAR TECHNOLOGICAL UNIVERSITY, LONERE, RAIGAD | E198: 6036 | F198: Government College Of Engineering Kolhapur | G198: Maharashtra | H198: Kolhapur | I198: Karveer | J198: Kolhapur | K198: 416004 | L198: EN23233209 | N198: Male | O198: Hindu | P198: Open | R198: GOPENH | S198: Rural | T198: India | U198: Maharashtra | V198: Sangli | W198: Kadegaon | X198: Sonkire | Y198: 415303 | Z198: 23060361293059 | AA198: 23448 | AB198: 2024-25/416 | AC198: 2024-25/416 | AD198: 17546/- | AE198: Not Applicable | AF198: Unmarried | AG198: English | AH198: English | AI198: Regular | AJ198: 11293 | AK198: Electrical Engineering | AM198: UG | AN198: Second Year | AO198: Sem 3,sem4 | AP198: Elligible | AQ198: 45509 | AR198: Yes | AS198: 0 | AT198: 341000789748
B199: 2024-25 | C199: C-70713 | D199: DR. BABASAHEB AMBEDKAR TECHNOLOGICAL UNIVERSITY, LONERE, RAIGAD | E199: 6036 | F199: Government College Of Engineering Kolhapur | G199: Maharashtra | H199: Kolhapur | I199: Karveer | J199: Kolhapur | K199: 416004 | L199: EN23166943 | N199: Female | O199: Hindu | P199: Open | R199: ACAP | S199: Urban | T199: India | U199: Maharashtra | V199: Sangli | W199: Tasgaon | X199: Tasgaon (M Cl) | Y199: 416312 | Z199: 23060361293060 | AA199: 23410 | AB199: 2023-24/417 | AC199: 2023-24/417 | AE199: Not Applicable | AF199: Unmarried | AG199: English | AH199: English | AI199: Regular | AJ199: 11293 | AK199: Electrical Engineering | AM199: UG | AN199: Second Year | AO199: Sem 3,sem4 | AP199: Elligible | AQ199: 45509 | AR199: Yes | AS199: 0 | AT199: 120056622255
B200: 2024-25 | C200: C-70713 | D200: DR. BABASAHEB AMBEDKAR TECHNOLOGICAL UNIVERSITY, LONERE, RAIGAD | E200: 6036 | F200: Government College Of Engineering Kolhapur | G200: Maharashtra | H200: Kolhapur | I200: Karveer | J200: Kolhapur | K200: 416004 | L200: EN23100065 | N200: Male | O200: Hindu | P200: OBC | R200: GOBCH | S200: Rural | T200: India | U200: Maharashtra | V200: Amravati | W200: Dhamangaon Railway | X200: Giroli | Y200: 442302 | Z200: 23060361293061 | AA200: 23411 | AB200: 2024-25/417 | AC200: 2024-25/417 | AE200: Not Applicable | AF200: Unmarried | AG200: English | AH200: English | AI200: Regular | AJ200: 11293 | AK200: Electrical Engineering | AM200: UG | AN200: Second Year | AO200: Sem 3,sem4 | AP200: Elligible | AQ200: 45509 | AR200: Yes | AS200: 0 | AT200: 281927412872
...

Sheet Student_section_data
E1: Academic Year 2023-24 Admitted Data
B3: 1 | C3: 2 | D3: 3 | E3: 4 | F3: 5 | G3: 6 | H3: 7 | I3: 8 | J3: 9 | K3: 10 | L3: 11 | M3: 12 | N3: 13 | O3: 14 | P3: 15 | Q3: 16 | R3: 17 | S3: 18 | T3: 19 | U3: 20 | W3: 21 | X3: 22 | Y3: 23 | Z3: 24 | AA3: 25 | AB3: 26 | AC3: 27 | AD3: 28
B4: Sr.No. | C4: Application Form No. | D4: University PRN | E4: Name of student | F4: Roll Number | G4: Gender (Male/Female/Transgender) | H4: Religion (Hindu,Muslim,Christian, Parsi,Buddhist,Sikh,jain, Jew) | I4: Category (EWS,Foreign National,General, Not Available,OBC,Others,PWD,SBC, SC, SEBC,ST,VJ, NT) | J4: Cast Name (e.g Brahmin/Sonar/...) | K4: Admitted Category (EWS,Foreign National,General, Not Available,OBC,Others,PWD,SBC, SC, SEBC,ST,VJ, NT) | L4: Student Location Category (Rural/Urban) | M4: Student Country | N4: Student State | O4: Student District | P4: Student Taluka | Q4: Student City / Village | R4: Student Location Pin Code | S4: Admission Date in FY(2023-24) | T4: Receipt Number FY | U4: Receipt Amount in FY (2023-24) | V4: Elligible in SY | W4: Admission Date in SY | X4: Receipt Number SY | Y4: Receipt Amount in SY(2024-25) | Z4: Physical Disability Enter the Disabilities of the Sttudents (Blindness,Low Vision,Hearing Impairment,Locomotor Disability,Leprosy Cured,Mental illness,Cerebral Palsy,Intellectual Disability,Muscular Dystrophy Parkinson's Disease,Acid Attack Victim,Sickle Cell Disease,Haemophilia,Thalassemia, Speech and Language Disabilities, Multiple Sclerosis,Specific Learning Disabilities,Chronic Neurological Conditions,Autism Spectrum Disorder Dwarfism) | AA4: Marital Status (Deserted,Divorced, Married, Unmarried, Widowed) | AB4: Program Code | AC4: Program Code (Name of the course under program type) | AD4: APAAR ID (ABC ID) (12 - digit number APAAR ID of students that is earlier known as ABC ID (123456789012))
B5: 1 | C5: EN23156538 | D5: 23060361242001 | E5: =VLOOKUP(D5,Sheet2!A2:'Sheet2'!D317,2,FALSE) -> PATIL SHIVTEJ JAYPRAKASH | F5: 23149 | G5: Male | H5: Hindu | I5: Open | K5: EWS | L5: Rural | M5: India | N5: Maharashtra | O5: Sangli | P5: Walwa | Q5: Uran Islampur (M Cl) | R5: 415409 | U5: 17546/- | V5: Elligible | X5: 2024-25/320 | Z5: Not Applicable | AA5: Unmarried | AB5: 11242 | AC5: Computer Science and Engineering | AD5: 605880265207
B6: 2 | C6: EN23270294 | D6: 23060361242002 | E6: =VLOOKUP(D6,Sheet2!A3:'Sheet2'!D318,2,FALSE) -> PATIL NIRMAL RAJENDRA | F6: 23146 | G6: Male | H6: Hindu | I6: OBC | K6: GOBCO | L6: Rural | M6: India | N6: Maharashtra | O6: Jalgaon | P6: Dharangaon | Q6: Rotwad | R6: 425105 | U6: 10046/- | V6: Elligible | X6: 2023-24/321 | Z6: Not Applicable | AA6: Unmarried | AB6: 11242 | AC6: Computer Science and Engineering | AD6: 836028351886
B7: 3 | C7: EN23253637 | D7: 23060361242003 | E7: =VLOOKUP(D7,Sheet2!A4:'Sheet2'!D319,2,FALSE) -> DESHMUKH SUSHRUT SHEKHAR | F7: 23108 | G7: Male | H7: Hindu | I7: Open | K7: ACAP | L7: Rural | M7: India | N7: Maharashtra | O7: Raigad | P7: Khalapur | Q7: Honad | R7: 410203 | U7: 26046/- | V7: Elligible | X7: 2024-25/321 | Z7: Not Applicable | AA7: Unmarried | AB7: 11242 | AC7: Computer Science and Engineering | AD7: 323555912835
B8: 4 | C8: EN23254563 | D8: 23060361242004 | E8: =VLOOKUP(D8,Sheet2!A5:'Sheet2'!D320,2,FALSE) -> HITESH CHANDRAKANT BHUSARA | F8: 23112 | G8: Male | H8: Hindu | I8: ST | K8: GSTH | L8: Rural | M8: India | N8: Maharashtra | O8: Palghar | P8: Vikramgad | Q8: Vasuri | R8: 421303 | U8: 1621/- | V8: Elligible | X8: 2023-24/322 | Z8: Not Applicable | AA8: Unmarried | AB8: 11242 | AC8: Computer Science and Engineering | AD8: 802817008651
B9: 5 | C9: EN23187082 | D9: 23060361242005 | E9: =VLOOKUP(D9,Sheet2!A6:'Sheet2'!D321,2,FALSE) -> PUKALE AJAY SUNIL | F9: 23154 | G9: Male | H9: Hindu | I9: NT 2 (NT-C) | K9: GNT2H | L9: Rural | M9: India | N9: Maharashtra | O9: Sangli | P9: Atpadi | Q9: Banpuri | R9: 415306 | U9: 0/- | V9: Elligible | X9: 2024-25/322 | Z9: Not Applicable | AA9: Unmarried | AB9: 11242 | AC9: Computer Science and Engineering | AD9: 267273146627
B10: 6 | C10: EN23251094 | D10: 23060361242006 | E10: =VLOOKUP(D10,Sheet2!A7:'Sheet2'!D322,2,FALSE) -> THITE ATUL NETAJI | F10: 23167 | G10: Male | H10: Hindu | I10: Open | K10: GOPENO | L10: Rural | M10: India | N10: Maharashtra | O10: Solapur | P10: Pandharpur | Q10: Bhose | R10: 413315 | U10: 17546/- | V10: Elligible | X10: 2023-24/323 | Z10: Not Applicable | AA10: Unmarried | AB10: 11242 | AC10: Computer Science and Engineering | AD10: 781639551721
B11: 7 | C11: EN23250898 | D11: 23060361242007 | E11: =VLOOKUP(D11,Sheet2!A8:'Sheet2'!D323,2,FALSE) -> INAMDAR BHAGYASHRI UMESH | F11: 23115 | G11: Female | H11: Hindu | I11: Open | K11: EWS | L11: Urban | M11: India | N11: Maharashtra | O11: Kolhapur | P11: Karvir | Q11: Kolhapur (M Corp.) | R11: 416012 | U11: 17546/- | V11: Elligible | X11: 2024-25/323 | Z11: Not Applicable | AA11: Unmarried | AB11: 11242 | AC11: Computer Science and Engineering | AD11: 351040668378
B12: 8 | C12: EN23125066 | D12: 23060361242008 | E12: =VLOOKUP(D12,Sheet2!A9:'Sheet2'!D324,2,FALSE) -> INAMDAR AFFAN SAIF | F12: 23114 | G12: Male | H12: Muslim | I12: Open | K12: GOPENH | L12: Urban | M12: India | N12: Maharashtra | O12: Sangli | P12: Walwa | Q12: Ashta (M Cl) | R12: 416301 | U12: 17546/- | V12: Elligible | X12: 2023-24/324 | Z12: Not Applicable | AA12: Unmarried | AB12: 11242 | AC12: Computer Science and Engineering | AD12: 660158417433
B13: 9 | C13: EN23165043 | D13: 23060361242009 | E13: =VLOOKUP(D13,Sheet2!A10:'Sheet2'!D325,2,FALSE) -> MADAVI HARSH LAXMAN | F13: 23135 | G13: Male | H13: Hindu | I13: ST | K13: GSTH | L13: Urban | M13: India | N13: Maharashtra | O13: Chandrapur | P13: Chandrapur | Q13: Chandrapur | R13: 442401 | U13: 1621/- | V13: Elligible | X13: 2024-25/324 | Z13: Not Applicable | AA13: Unmarried | AB13: 11242 | AC13: Computer Science and Engineering | AD13: 407782827857
B14: 10 | C14: EN23234429 | D14: 23060361242010 | E14: =VLOOKUP(D14,Sheet2!A11:'Sheet2'!D326,2,FALSE) -> MANKAR PRANAV GAJANAN | F14: 23136 | G14: Male | H14: Hindu | I14: OBC | K14: ACAP | L14: Rural | M14: India | N14: Maharashtra | O14: Aurangabad | P14: Aurangabad | Q14: Aurangabad (M Corp.) | R14: 431136 | U14: 25046/- | V14: Elligible | X14: 2023-24/325 | Z14: Not Applicable | AA14: Unmarried | AB14: 11242 | AC14: Computer Science and Engineering | AD14: 641151883947
B15: 11 | C15: EN23245684 | D15: 23060361242011 | E15: =VLOOKUP(D15,Sheet2!A12:'Sheet2'!D327,2,FALSE) -> CHOUGULE DIPALI NAVANATH | F15: 23106 | G15: Female | H15: Hindu | I15: NT 2 (NT-C) | K15: LOPENH | L15: Rural | M15: India | N15: Maharashtra | O15: Sangli | P15: Jat | Q15: Khairao | R15: 416404 | U15: 10046/- | V15: Elligible | X15: 2024-25/325 | Z15: Not Applicable | AA15: Unmarried | AB15: 11242 | AC15: Computer Science and Engineering | AD15: 230336667045
B16: 12 | C16: EN23258899 | D16: 23060361242012 | E16: =VLOOKUP(D16,Sheet2!A13:'Sheet2'!D328,2,FALSE) -> BODKHE OM KAILAS | F16: 23104 | G16: Male | H16: Hindu | I16: OBC | K16: PWDOPENH | L16: Urban | M16: India | N16: Maharashtra | O16: Buldhana | P16: Chikhli | Q16: Chikhli (M Cl) | R16: 443201 | U16: 10046/- | V16: Elligible | X16: 2023-24/326 | Z16: Low-Vision | AA16: Unmarried | AB16: 11242 | AC16: Computer Science and Engineering | AD16: 298767095627
... B44: 40 | C44: EN23106525 | D44: 23060361242040 | E44: =VLOOKUP(D44,Sheet2!A41:'Sheet2'!D356,2,FALSE) -> CHAITANYA NITIN ZANJURNE | F44: 23169 | G44: Male | H44: Hindu | I44: Open | K44: ACAP | L44: Rural | M44: India | N44: Maharashtra | O44: Satara | P44: Koregaon | Q44: Tadawale s.koregaon | R44: 415001 | U44: 25046/- | V44: Elligible | X44: 2023-24/340 | Z44: Not Applicable | AA44: Unmarried | AB44: 11242 | AC44: Computer Science and Engineering | AD44: 815210988317
B45: 41 | C45: EN23154691 | D45: 23060361242041 | E45: =VLOOKUP(D45,Sheet2!A43:'Sheet2'!D358,2,FALSE) -> JAGTAP NISHANT SACHIN | F45: 23120 | G45: Male | H45: Hindu | I45: Open | K45: TFWS | L45: Rural | M45: India | N45: Maharashtra | O45: Latur | P45: Ausa | Q45: Kumtha | R45: 413516 | U45: 17546/- | V45: Elligible | X45: 2023-24/341 | Z45: Not Applicable | AA45: Not Applicable | AB45: 11242 | AC45: Computer Science and Engineering | AD45: 642069027177
B46: 42 | C46: EN23240790 | D46: 23060361242042 | E46: =VLOOKUP(D46,Sheet2!A44:'Sheet2'!D359,2,FALSE) -> JADHAV SAIE BALASAHEB | F46: 23119 | G46: Female | H46: Hindu | I46: Open | K46: LOPENH | L46: Rural | M46: India | N46: Maharashtra | O46: Kolhapur | P46: Kagal | Q46: Vhanali | R46: 416221 | U46: 10046/- | V46: Elligible | X46: 2024-25/341 | Z46: Not Applicable | AA46: Not Applicable | AB46: 11242 | AC46: Computer Science and Engineering | AD46: 767473727872
B47: 43 | C47: EN23245293 | D47: 23060361242043 | E47: =VLOOKUP(D47,Sheet2!A45:'Sheet2'!D360,2,FALSE) -> KESARKAR SHRAVANI MAHESH | F47: 23124 | G47: Female | H47: Hindu | I47: Open | K47: TFWS | L47: Rural | M47: India | N47: Maharashtra | O47: Kolhapur | P47: Karvir | Q47: Balinge | R47: 416010 | U47: 17546/- | V47: Elligible | X47: 2023-24/342 | Z47: Not Applicable | AA47: Not Applicable | AB47: 11242 | AC47: Computer Science and Engineering | AD47: 601870514481
B48: 44 | C48: EN23129471 | D48: 23060361242044 | E48: =VLOOKUP(D48,Sheet2!A46:'Sheet2'!D361,2,FALSE) -> KULKARNI AMRUTA LAXMAN | F48: 23132 | G48: Female | H48: Hindu | I48: Open | K48: EWS | L48: Rural | M48: India | N48: Maharashtra | O48: Satara | P48: Man | Q48: Ranand | R48: 415508 | U48: 10046/- | V48: Elligible | X48: 2024-25/342 | Z48: Not Applicable | AA48: Not Applicable | AB48: 11242 | AC48: Computer Science and Engineering | AD48: 793445560148
B49: 45 | C49: EN23231317 | D49: 23060361242045 | E49: =VLOOKUP(D49,Sheet2!A47:'Sheet2'!D362,2,FALSE) -> PATIL SNEHA SURESH | F49: 23151 | G49: Female | H49: Hindu | I49: Open | K49: DEFOPENS | L49: Rural | M49: India | N49: Maharashtra | O49: Sangli | P49: Shirala | Q49: Kokarud | R49: 415405 | U49: 10046/- | V49: Elligible | X49: 2023-24/343 | Z49: Not Applicable | AA49: Not Applicable | AB49: 11242 | AC49: Computer Science and Engineering | AD49: 925653939414
B50: 46 | C50: EN23135666 | D50: 23060361242046 | E50: =VLOOKUP(D50,Sheet2!A48:'Sheet2'!D363,2,FALSE) -> MADHURA SATISH SHINDE | F50: 23160 | G50: Female | H50: Hindu | I50: OBC | K50: LOBCH | L50: Urban | M50: India | N50: Maharashtra | O50: Satara | P50: Karad | Q50: Kalvade | R50: 415539 | U50: 17546/- | V50: Elligible | X50: 2024-25/343 | Z50: Not Applicable | AA50: Not Applicable | AB50: 11242 | AC50: Computer Science and Engineering | AD50: 696954191565
B51: 47 | C51: EN23201439 | D51: 23060361242047 | E51: =VLOOKUP(D51,Sheet2!A49:'Sheet2'!D364,2,FALSE) -> PATIL SANSKRUTI SANJAY | F51: 23148 | G51: Female | H51: Hindu | I51: Open | K51: LOPENH | L51: Rural | M51: India | N51: Maharashtra | O51: Kolhapur | P51: Gadhinglaj | Q51: Arjunwadi | R51: 416504 | U51: 10046/- | V51: Elligible | X51: 2023-24/344 | Z51: Not Applicable | AA51: Not Applicable | AB51: 11242 | AC51: Computer Science and Engineering | AD51: 170779418452
B52: 48 | C52: EN23104008 | D52: 23060361242048 | E52: =VLOOKUP(D52,Sheet2!A50:'Sheet2'!D365,2,FALSE) -> PATIL ARYA MILIND | F52: 23144 | G52: Female | H52: Hindu | I52: NT 2 (NT-C) | K52: LNT2H | L52: Rural | M52: India | N52: Maharashtra | O52: Kolhapur | P52: Shirol | Q52: Shirdhon | R52: 416121 | U52: 17546/- | V52: Elligible | X52: 2024-25/344 | Z52: Not Applicable | AA52: Not Applicable | AB52: 11242 | AC52: Computer Science and Engineering | AD52: 289447727921
B53: 49 | C53: EN23256547 | D53: 23060361242049 | E53: =VLOOKUP(D53,Sheet2!A51:'Sheet2'!D366,2,FALSE) -> SURYAWANSHI SAYALI VISHNU | F53: 23164 | G53: Female | H53: Hindu | I53: Open | K53: LOPENO | L53: Rural | M53: India | N53: Maharashtra | O53: Osmanabad | P53: Tuljapur | Q53: Tuljapur | R53: 413601 | U53: 10046/- | V53: Elligible | X53: 2023-24/345 | Z53: Not Applicable | AA53: Not Applicable | AB53: 11242 | AC53: Computer Science and Engineering | AD53: 909058215377
B54: 50 | C54: EN23208925 | D54: 23060361242050 | E54: =VLOOKUP(D54,Sheet2!A52:'Sheet2'!D367,2,FALSE) -> KHARMATE PAVITRA AMIT | F54: 23128 | G54: Female | H54: Hindu | I54: NT 3 (NT-D) | K54: GNT3H | L54: Urban | M54: India | N54: Maharashtra | O54: Sangli | P54: Miraj | Q54: Inam Dhamani | R54: 416416 | U54: 10046/- | V54: Elligible | X54: 2024-25/345 | Z54: Not Applicable | AA54: Not Applicable | AB54: 11242 | AC54: Computer Science and Engineering | AD54: 323655724196
B55: 51 | C55: EN23103281 | D55: 23060361242051 | E55: =VLOOKUP(D55,Sheet2!A53:'Sheet2'!D368,2,FALSE) -> SHAIKH UMAR TAYYAB | F55: 23158 | G55: Male | H55: Muslim | I55: OBC | K55: GOPENH | L55: Urban | M55: India | N55: Maharashtra | O55: Satara | P55: Satara | Q55: Kodoli (CT) | R55: 415004 | U55: 25046/- | V55: Elligible | X55: 2023-24/346 | Z55: Not Applicable | AA55: Not Applicable | AB55: 11242 | AC55: Computer Science and Engineering | AD55: 234572816522
B56: 52 | C56: EN23125035 | D56: 23060361242052 | E56: =VLOOKUP(D56,Sheet2!A54:'Sheet2'!D369,2,FALSE) -> TEJAS GANESH KHALKAR | F56: 23125 | G56: Male | H56: Hindu | I56: Open | K56: ACAP | L56: Rural | M56: India | N56: Maharashtra | O56: Satara | P56: Karad | Q56: Khalkarwadi | R56: 415109 | U56: 17546/- | V56: Left | X56: 2024-25/346 | Z56: Not Applicable | AA56: Not Applicable | AB56: 11242 | AC56: Computer Science and Engineering | AD56: 896488013466
... B58: 54 | C58: EN23154302 | D58: 23060361242054 | E58: =VLOOKUP(D58,Sheet2!A56:'Sheet2'!D371,2,FALSE) -> DURUGAWAR PRAJWAL RAJENDRA | F58: 23110 | G58: Male | H58: Hindu | I58: NT 1 (NT-B) | K58: GOPENO | L58: Rural | M58: India | N58: Maharashtra | O58: Wardha | P58: Wardha | Q58: Bhiwapur | R58: 442001 | U58: 10046/- | V58: Elligible | X58: 2024-25/347 | Z58: Not Applicable | AA58: Not Applicable | AB58: 11242 | AC58: Computer Science and Engineering | AD58: 915527162120
B59: 55 | C59: EN23143939 | D59: 23060361242055 | E59: =VLOOKUP(D59,Sheet2!A42:'Sheet2'!D357,2,FALSE) -> SANVEDYA NEWARE | F59: 23139 | G59: Male | H59: Hindu | I59: SBC | K59: GOPENO | L59: Urban | M59: India | N59: Maharashtra | O59: Wardha | P59: Wardha | Q59: Wardha (M Cl) | R59: 442001 | U59: 10046/- | V59: Elligible | X59: 2024-25/340 | Z59: Not Applicable | AA59: Unmarried | AB59: 11242 | AC59: Computer Science and Engineering | AD59: 492448852601
B60: 56 | C60: EN23170262 | D60: 23060361242056 | E60: =VLOOKUP(D60,Sheet2!A57:'Sheet2'!D372,2,FALSE) -> KODAVATE HRUTUJA SATISHRAO | F60: 23130 | G60: Female | H60: Hindu | I60: ST | K60: LSTH | L60: Urban | M60: India | N60: Maharashtra | O60: Amravati | P60: Dhamangaon Railway | Q60: Dattapur Dhamangaon (M Cl) | R60: 444709 | U60: 1621/- | V60: Elligible | X60: 2023-24/348 | Z60: Not Applicable | AA60: Not Applicable | AB60: 11242 | AC60: Computer Science and Engineering | AD60: 659675627536
B61: 57 | C61: EN23165206 | D61: 23060361242057 | E61: =VLOOKUP(D61,Sheet2!A58:'Sheet2'!D373,2,FALSE) -> PARADHI SHRUTI RAJU | F61: 23141 | G61: Female | H61: Hindu | I61: OBC | K61: PWDROBCH | L61: Rural | M61: India | N61: Maharashtra | O61: Wardha | P61: Hinganghat | Q61: Kangaon | R61: 442101 | U61: 10046/- | V61: Elligible | X61: 2024-25/348 | Z61: Locomotor Disability | AA61: Locomotor Disability | AB61: 11242 | AC61: Computer Science and Engineering | AD61: 485684680972
B62: 58 | C62: EN23231080 | D62: 23060361242058 | E62: =VLOOKUP(D62,Sheet2!A59:'Sheet2'!D374,2,FALSE) -> AIWALE SANKET SURESH | F62: 23101 | G62: Male | H62: Hindu | I62: SC | K62: GSCH | L62: Urban | M62: India | N62: Maharashtra | O62: Sangli | P62: Atpadi | Q62: Bhingewadi | R62: 415301 | U62: 1621/- | V62: Elligible | X62: 2023-24/349 | Z62: Not Applicable | AA62: Not Applicable | AB62: 11242 | AC62: Computer Science and Engineering | AD62: 400116219457
B63: 59 | C63: EN23170809 | D63: 23060361242059 | E63: =VLOOKUP(D63,Sheet2!A60:'Sheet2'!D375,2,FALSE) -> SHELAKE PRANALI MAHADEV | F63: 23159 | G63: Female | H63: Hindu | I63: Open | K63: ACAP | L63: Rural | M63: India | N63: Maharashtra | O63: Kolhapur | P63: Panhala | Q63: Satarde | R63: 416205 | U63: 25046/- | V63: Elligible | X63: 2024-25/349 | Z63: Not Applicable | AA63: Not Applicable | AB63: 11242 | AC63: Computer Science and Engineering | AD63: 141129263489
B64: 60 | C64: EN23200117 | D64: 23060361242060 | E64: =VLOOKUP(D64,Sheet2!A61:'Sheet2'!D376,2,FALSE) -> CHAVAN NIYATI VIJAY | F64: 23105 | G64: Female | H64: Hindu | I64: SC | K64: LSCH | L64: Urban | M64: India | N64: Maharashtra | O64: Kolhapur | P64: Hatkanangle | Q64: Ichalkaranji (M Cl) | R64: 416115 | U64: 1621/- | V64: Elligible | X64: 2023-24/350 | Z64: Not Applicable | AA64: Not Applicable | AB64: 11242 | AC64: Computer Science and Engineering | AD64: 786942678247
B65: 61 | C65: EN23155754 | D65: 23060361242061 | E65: =VLOOKUP(D65,Sheet2!A62:'Sheet2'!D377,2,FALSE) -> KUMBHAR ADITYA KERABA | F65: 23133 | G65: Male | H65: Hindu | I65: OBC | K65: GOPENH | L65: Rural | M65: India | N65: Maharashtra | O65: Kolhapur | P65: Panhala | Q65: Mohare | R65: 416114 | U65: 10046/- | V65: Elligible | X65: 2024-25/350 | Z65: Not Applicable | AA65: Not Applicable | AB65: 11242 | AC65: Computer Science and Engineering | AD65: 694244144718
B66: 62 | C66: EN23153834 | D66: 23060361242062 | E66: =VLOOKUP(D66,Sheet2!A63:'Sheet2'!D378,2,FALSE) -> MOHITE ANIKET DHANAJI | F66: 23137 | G66: Male | H66: Hindu | I66: Open | K66: PWDOPENH | L66: Rural | M66: India | N66: Maharashtra | O66: Sangli | P66: Kadegaon | Q66: Bombalewadi | R66: 415304 | U66: 17546/- | V66: Elligible | X66: 2023-24/351 | Z66: Locomotor Disability | AA66: Locomotor Disability | AB66: 11242 | AC66: Computer Science and Engineering | AD66: 893362829498
B67: 63 | C67: EN23220807 | D67: 23060361242063 | E67: =VLOOKUP(D67,Sheet2!A64:'Sheet2'!D379,2,FALSE) -> KOLI ROHAN RAJARAM | F67: 23131 | G67: Male | H67: Hindu | I67: SBC | K67: GOPENH | L67: Rural | M67: India | N67: Maharashtra | O67: Kolhapur | P67: Shirol | Q67: Takli | R67: 416108 | U67: 10046/- | V67: Elligible | X67: 2024-25/351 | Z67: Not Applicable | AA67: Not Applicable | AB67: 11242 | AC67: Computer Science and Engineering | AD67: 734856933450
B68: 64 | C68: EN23180954 | D68: 23060361242064 | E68: =VLOOKUP(D68,Sheet2!A65:'Sheet2'!D380,2,FALSE) -> MADANE SATYAM BHIMARAO | F68: 23134 | G68: Male | H68: Hindu | I68: DT/VJ | K68: GOPENH | L68: Rural | M68: India | N68: Maharashtra | O68: Satara | P68: Khatav | Q68: Kokarale | R68: 415527 | U68: 10046/- | V68: Elligible | X68: 2023-24/352 | Z68: Not Applicable | AA68: Not Applicable | AB68: 11242 | AC68: Computer Science and Engineering | AD68: 525996560460
B69: 65 | C69: EN23220748 | D69: 23060361242065 | E69: =VLOOKUP(D69,Sheet2!A66:'Sheet2'!D381,2,FALSE) -> GAIKWAD BALKRISHNA MAHADEV | F69: 23111 | G69: Male | H69: Hindu | I69: Open | K69: EWS | L69: Rural | M69: India | N69: Maharashtra | O69: Kolhapur | P69: Shirol | Q69: Takli | R69: 416108 | U69: 17546/- | V69: Elligible | X69: 2024-25/352 | Z69: Not Applicable | AA69: Not Applicable | AB69: 11242 | AC69: Computer Science and Engineering | AD69: 844607448169
...

Sheet Sheet2
A2: 23060361242001 | B2: PATIL SHIVTEJ JAYPRAKASH | D2: 23149
A3: 23060361242002 | B3: PATIL NIRMAL RAJENDRA | D3: 23146
A4: 23060361242003 | B4: DESHMUKH SUSHRUT SHEKHAR | D4: 23108
A5: 23060361242004 | B5: HITESH CHANDRAKANT BHUSARA | D5: 23112
A6: 23060361242005 | B6: PUKALE AJAY SUNIL | D6: 23154
A7: 23060361242006 | B7: THITE ATUL NETAJI | D7: 23167
A8: 23060361242007 | B8: INAMDAR BHAGYASHRI UMESH | D8: 23115
A9: 23060361242008 | B9: INAMDAR AFFAN SAIF | D9: 23114
A10: 23060361242009 | B10: MADAVI HARSH LAXMAN | D10: 23135
A11: 23060361242010 | B11: MANKAR PRANAV GAJANAN | D11: 23136
A12: 23060361242011 | B12: CHOUGULE DIPALI NAVANATH | D12: 23106
A13: 23060361242012 | B13: BODKHE OM KAILAS | D13: 23104
... A317: 23060361615051 | B317: GALAVE SUSHANT SHIVAJI | D317: 23509
A318: #N/A | B318: PATIL SAIRAJ DIVAKAR | D318: #N/A
A319: #N/A | B319: BHISE PRADIP PRABHAKAR | D319: #N/A
A320: #N/A | B320: KAKADE RAVINA DINESH | D320: #N/A
A321: #N/A | B321: SURYAWANSHI GOVIND RAJESH | D321: #N/A
A322: 0 | B322: INGALE VIJAY SUNIL | D322: 0
A323: 0 | B323: SANGALE NARAYAN NAVNATH | D323: 0
